Workbook

Sheet Инструкция
A1: ФИНАНСОВАЯ МОДЕЛЬ: горнорудный инвестиционный офис (Казахстан)
A3: Назначение | B3: Модель для двух решений: (1) стоит ли сделка по хвостохранилищу за $8M, (2) какая экономика у фонда $30M. Все входные параметры собраны на листе «Допущения».
A5: КАК ПОЛЬЗОВАТЬСЯ
A6: Шаг 1 | B6: Откройте лист «Допущения». Меняйте ТОЛЬКО ячейки с синим шрифтом на жёлтом фоне.
A7: Шаг 2 | B7: Лист «Проект» пересчитается автоматически: денежный поток по годам, NPV, IRR, мультипликатор.
A8: Шаг 3 | B8: Лист «Сценарии» показывает три ценовых сценария рядом и таблицу чувствительности к цене золота и извлечению.
A9: Шаг 4 | B9: Лист «Фонд» — экономика фонда $30M: комиссии, waterfall, carry, доходность LP и GP.
A10: Шаг 5 | B10: Лист «Бюджет» — разовые и операционные расходы офиса, зарплаты команды.
A12: ЦВЕТОВОЙ КОД
A13: Синий шрифт | B13: Введённое значение — можно и нужно менять.
A14: Чёрный шрифт | B14: Формула — не трогать.
A15: Зелёный шрифт | B15: Ссылка на другой лист — не трогать.
A16: Жёлтая заливка | B16: Ключевое допущение, которое сильнее всего влияет на результат.
A18: ПРЕДУПРЕЖДЕНИЕ
A19: Статус данных | B19: ВСЕ параметры хвостохранилища (объём, содержания, извлечение, CAPEX, OPEX) — ИЛЛЮСТРАТИВНЫЕ ПЛЕЙСХОЛДЕРЫ. Они НЕ основаны на данных по вашему объекту и НЕ МОГУТ показываться инвестору как факт.
A20: Что делать | B20: Заменить их результатами собственного опробования, металлургических тестов и отчёта Компетентного лица (KAZRC / JORC). До этого модель показывает только структуру и чувствительность, а не стоимость актива.
A21: Цены металлов | B21: Спот на 10.08.2026: золото $4 376/унц., серебро $65,86/унц. Это исторически экстремальные уровни. Базовый сценарий сознательно консервативен.
A22: Налоги | B22: Учтён коэффициент 0,1 к НДПИ для ТМО (ст. 783 НК РК, с 01.01.2026) и опция соглашения о переработке ТПИ (гл. 84 НК РК: КПН = 0 на 10 лет). Применимость обеих льгот к вашей конфигурации требует письменного заключения налогового консультанта.
A24: Источники | B24: Полный список источников — в документе 02-podrobnyy-plan.md, раздел 14.3.

Sheet Допущения
A1: ДОПУЩЕНИЯ — единственный лист, который вы редактируете
A3: Параметр | B3: Значение | C3: Ед. | D3: Комментарий / источник
A5: 1. ЦЕНЫ МЕТАЛЛОВ И МАКРО
A6: Цена золота — базовый сценарий | B6: 3200 | C6: $/унц. | D6: Консервативно к споту. Это цифра для разговора с инвестором.
A7: Цена золота — спот 10.08.2026 | B7: 4376 | C7: $/унц. | D7: Факт: Trading Economics / JM Bullion, 10.08.2026.
A8: Цена золота — пессимистичный | B8: 2600 | C8: $/унц. | D8: Стресс-сценарий.
A9: Цена серебра — базовый | B9: 45 | C9: $/унц. | D9: Консервативно к споту $65,86.
A10: Цена серебра — спот 10.08.2026 | B10: 65.86 | C10: $/унц. | D10: Факт на 10.08.2026.
A11: Цена серебра — пессимистичный | B11: 35 | C11: $/унц. | D11: Стресс-сценарий.
A12: Курс KZT/USD | B12: 470 | C12: ₸/$ | D12: Официальный курс НБ РК, август 2026 (~473,6).
A13: МРП 2026 | B13: 4325 | C13: ₸ | D13: Закон о республиканском бюджете на 2026–2028 гг.
A14: Тройских унций в килограмме | B14: 32.1507 | C14: унц./кг | D14: Константа. Не менять.
A16: 2. ХВОСТОХРАНИЛИЩЕ — РЕСУРС И ПЕРЕРАБОТКА ⚠ ВСЁ НИЖЕ — ПЛЕЙСХОЛДЕРЫ
A17: Объём хвостов | B17: 2500 | C17: тыс. т | D17: ЗАМЕНИТЬ данными топосъёмки и бурения.
A18: Содержание золота | B18: 0.6 | C18: г/т | D18: ЗАМЕНИТЬ данными собственного опробования.
A19: Содержание серебра | B19: 5 | C19: г/т | D19: ЗАМЕНИТЬ данными собственного опробования.
A20: Извлечение золота | B20: 0.55 | C20: % | D20: САМЫЙ ЧУВСТВИТЕЛЬНЫЙ ПАРАМЕТР. Только металлургические тесты на своих пробах.
A21: Извлечение серебра | B21: 0.25 | C21: % | D21: Из хвостов серебро извлекается заметно хуже золота.
A22: Производительность фабрики | B22: 625 | C22: тыс.т/г | D22: Задаёт срок проекта: объём / производительность.
A23: CAPEX (фабрика, пруд, инфраструктура) | B23: 18000 | C23: $ тыс. | D23: Хвосты уже измельчены — дробление и помол не нужны, это главная экономия против гринфилда.
A24: OPEX | B24: 16 | C24: $/т | D24: Реагенты, энергия, персонал, перекачка пульпы.
A25: Цена покупки актива | B25: 8000 | C25: $ тыс. | D25: Заявленная продавцом цена сделки.
A26: Бюджет due diligence | B26: 150 | C26: $ тыс. | D26: Бурение, пробы, металлургия, CPR, юр./эколог. проверка. 1–2% от суммы сделки.
A27: G&A + рекультивация за весь проект | B27: 8000 | C27: $ тыс. | D27: Административные расходы плюс обязательства по закрытию.
A29: 3. НАЛОГИ КАЗАХСТАНА
A30: Базовая ставка НДПИ (золото/серебро) | B30: 0.09 | C30: % | D30: С 2026 прогрессивная шкала 7,5–11% в зависимости от цены. При текущих ценах — верх шкалы.
A31: Коэффициент НДПИ для ТМО | B31: 0.1 | C31: коэф. | D31: Ст. 783 НК РК с 01.01.2026: НДПИ на ископаемые из ТМО снижен в 10 раз. Объект обложения — реализованные, а не добытые.
A32: Ставка КПН | B32: 0.2 | C32: % | D32: Корпоративный подоходный налог РК.
A33: Соглашение о переработке ТПИ (1=да) | B33: 0 | C33: флаг | D33: Гл. 84 НК РК: освобождение от КПН и земельного налога на 10 лет, налога на имущество на 8 лет, НДС и пошлин на импорт оборудования. Поставьте 1, чтобы увидеть эффект.
A34: Ставка дисконтирования | B34: 0.12 | C34: % | D34: Для NPV проекта. Для горного проекта в РК разумный диапазон 10–15%.
A36: 4. ФОНД
A37: Размер фонда (обязательства) | B37: 30000 | C37: $ тыс. | D37: Цель Фонда I. Соответствует офису из 3–5 человек.
A38: GP commit | B38: 0.015 | C38: % | D38: Собственные деньги управляющих в фонде. Инвесторы требуют 1–3%.
A39: Management fee | B39: 0.02 | C39: % | D39: 2% от обязательств в инвестиционный период, далее от вложенного капитала по себестоимости.
A40: Carried interest | B40: 0.2 | C40: % | D40: Доля управляющего в прибыли сверх hurdle.
A41: Hurdle (preferred return) | B41: 0.08 | C41: % | D41: Годовая доходность, которую инвестор получает раньше carry.
A42: Средний срок для расчёта hurdle | B42: 5 | C42: лет | D42: Упрощение: накопленный preferred считается как C×((1+h)^t−1).
A43: Инвестиционный период | B43: 5 | C43: лет | D43: Годы, в которые fee считается от обязательств.
A44: Организационные расходы фонда | B44: 300 | C44: $ тыс. | D44: Юр. документы фонда, регистрация. Обычно ограничены 1% от размера фонда.
A45: Валовой мультипликатор (базовый) | B45: 2.6 | C45: x | D45: Сколько фонд возвращает на вложенный доллар до вычета carry.
...

Sheet Проект
A1: ПРОЕКТ: переработка хвостохранилища — денежный поток
A3: Сценарий цен: 1 = базовый · 2 = спот · 3 = пессимистичный | B3: 1
A5: РЕСУРС И МЕТАЛЛ
A6: Объём хвостов, тыс. т | B6: =Допущения!B17 -> 2500
A7: Содержание золота, г/т | B7: =Допущения!B18 -> 0.6
A8: Содержание серебра, г/т | B8: =Допущения!B19 -> 5
A9: Металл в хвостах — золото, кг | B9: =B6*B7 -> 1500
A10: Металл в хвостах — серебро, кг | B10: =B6*B8 -> 12500
A11: Извлечение золота, % | B11: =Допущения!B20 -> 0.55
A12: Извлечение серебра, % | B12: =Допущения!B21 -> 0.25
A13: Извлекаемое золото, кг | B13: =B9*B11 -> 825
A14: Извлекаемое серебро, кг | B14: =B10*B12 -> 3125
A15: Извлекаемое золото, тр. унций | B15: =B13*Допущения!B14 -> 26524.327
A16: Извлекаемое серебро, тр. унций | B16: =B14*Допущения!B14 -> 100470.94
A17: Срок производства, лет | B17: =ROUND(B6/Допущения!B22,0) -> 4
A19: ЦЕНЫ ВЫБРАННОГО СЦЕНАРИЯ
A20: Цена золота, $/унц. | B20: =CHOOSE($B$3,Допущения!B6,Допущения!B7,Допущения!B8) -> 3200
A21: Цена серебра, $/унц. | B21: =CHOOSE($B$3,Допущения!B9,Допущения!B10,Допущения!B11) -> 45
A23: ДЕНЕЖНЫЙ ПОТОК ПРОЕКТА, $ тыс.
A24: Показатель | C24: Год 0 | D24: Год 1 | E24: Год 2 | F24: Год 3 | G24: Год 4 | H24: Год 5 | I24: ИТОГО
A25: Признак года производства | C25: =IF(AND(0>=2,0<=1+$B$17),1,0) -> 0 | D25: =IF(AND(1>=2,1<=1+$B$17),1,0) -> 0 | E25: =IF(AND(2>=2,2<=1+$B$17),1,0) -> 1 | F25: =IF(AND(3>=2,3<=1+$B$17),1,0) -> 1 | G25: =IF(AND(4>=2,4<=1+$B$17),1,0) -> 1 | H25: =IF(AND(5>=2,5<=1+$B$17),1,0) -> 1
A27: Переработано руды, тыс. т | C27: =C25*Допущения!B22 -> 0 | D27: =D25*Допущения!B22 -> 0 | E27: =E25*Допущения!B22 -> 625 | F27: =F25*Допущения!B22 -> 625 | G27: =G25*Допущения!B22 -> 625 | H27: =H25*Допущения!B22 -> 625 | I27: =SUM(C27:H27) -> 2500
A28: Золото произведено, унц. | C28: =C25*$B$15/$B$17 -> 0 | D28: =D25*$B$15/$B$17 -> 0 | E28: =E25*$B$15/$B$17 -> 6631.0819 | F28: =F25*$B$15/$B$17 -> 6631.0819 | G28: =G25*$B$15/$B$17 -> 6631.0819 | H28: =H25*$B$15/$B$17 -> 6631.0819 | I28: =SUM(C28:H28) -> 26524.327
A29: Серебро произведено, унц. | C29: =C25*$B$16/$B$17 -> 0 | D29: =D25*$B$16/$B$17 -> 0 | E29: =E25*$B$16/$B$17 -> 25117.734 | F29: =F25*$B$16/$B$17 -> 25117.734 | G29: =G25*$B$16/$B$17 -> 25117.734 | H29: =H25*$B$16/$B$17 -> 25117.734 | I29: =SUM(C29:H29) -> 100470.94
A31: ВЫРУЧКА И РАСХОДЫ
A32: Выручка — золото | C32: =C28*$B$20/1000 -> 0 | D32: =D28*$B$20/1000 -> 0 | E32: =E28*$B$20/1000 -> 21219.462 | F32: =F28*$B$20/1000 -> 21219.462 | G32: =G28*$B$20/1000 -> 21219.462 | H32: =H28*$B$20/1000 -> 21219.462 | I32: =SUM(C32:H32) -> 84877.848
A33: Выручка — серебро | C33: =C29*$B$21/1000 -> 0 | D33: =D29*$B$21/1000 -> 0 | E33: =E29*$B$21/1000 -> 1130.298 | F33: =F29*$B$21/1000 -> 1130.298 | G33: =G29*$B$21/1000 -> 1130.298 | H33: =H29*$B$21/1000 -> 1130.298 | I33: =SUM(C33:H33) -> 4521.1922
A34: Выручка итого | C34: =C32+C33 -> 0 | D34: =D32+D33 -> 0 | E34: =E32+E33 -> 22349.76 | F34: =F32+F33 -> 22349.76 | G34: =G32+G33 -> 22349.76 | H34: =H32+H33 -> 22349.76 | I34: =SUM(C34:H34) -> 89399.04
A35: OPEX | C35: =-C27*Допущения!B24 -> 0 | D35: =-D27*Допущения!B24 -> 0 | E35: =-E27*Допущения!B24 -> -10000 | F35: =-F27*Допущения!B24 -> -10000 | G35: =-G27*Допущения!B24 -> -10000 | H35: =-H27*Допущения!B24 -> -10000 | I35: =SUM(C35:H35) -> -40000
A36: НДПИ (со скидкой 0,1 для ТМО) | C36: =-C34*Допущения!B30*Допущения!B31 -> 0 | D36: =-D34*Допущения!B30*Допущения!B31 -> 0 | E36: =-E34*Допущения!B30*Допущения!B31 -> -201.14784 | F36: =-F34*Допущения!B30*Допущения!B31 -> -201.14784 | G36: =-G34*Допущения!B30*Допущения!B31 -> -201.14784 | H36: =-H34*Допущения!B30*Допущения!B31 -> -201.14784 | I36: =SUM(C36:H36) -> -804.59136
A37: G&A и рекультивация | C37: =-C25*Допущения!B27/$B$17 -> 0 | D37: =-D25*Допущения!B27/$B$17 -> 0 | E37: =-E25*Допущения!B27/$B$17 -> -2000 | F37: =-F25*Допущения!B27/$B$17 -> -2000 | G37: =-G25*Допущения!B27/$B$17 -> -2000 | H37: =-H25*Допущения!B27/$B$17 -> -2000 | I37: =SUM(C37:H37) -> -8000
A38: EBITDA | C38: =C34+C35+C36+C37 -> 0 | D38: =D34+D35+D36+D37 -> 0 | E38: =E34+E35+E36+E37 -> 10148.612 | F38: =F34+F35+F36+F37 -> 10148.612 | G38: =G34+G35+G36+G37 -> 10148.612 | H38: =H34+H35+H36+H37 -> 10148.612 | I38: =SUM(C38:H38) -> 40594.449
A40: ИНВЕСТИЦИИ И НАЛОГ НА ПРИБЫЛЬ
A41: Покупка актива и due diligence | C41: =-(Допущения!B25+Допущения!B26) -> -8150 | D41: =0 -> 0 | E41: =0 -> 0 | F41: =0 -> 0 | G41: =0 -> 0 | H41: =0 -> 0 | I41: =SUM(C41:H41) -> -8150
A42: CAPEX | C42: =0 -> 0 | D42: =-Допущения!B23 -> -18000 | E42: =0 -> 0 | F42: =0 -> 0 | G42: =0 -> 0 | H42: =0 -> 0 | I42: =SUM(C42:H42) -> -18000
A43: Амортизация (для налога) | C43: =-C25*Допущения!B23/$B$17 -> 0 | D43: =-D25*Допущения!B23/$B$17 -> 0 | E43: =-E25*Допущения!B23/$B$17 -> -4500 | F43: =-F25*Допущения!B23/$B$17 -> -4500 | G43: =-G25*Допущения!B23/$B$17 -> -4500 | H43: =-H25*Допущения!B23/$B$17 -> -4500 | I43: =SUM(C43:H43) -> -18000
A44: Налогооблагаемая прибыль | C44: =MAX(0,C38+C43) -> 0 | D44: =MAX(0,D38+D43) -> 0 | E44: =MAX(0,E38+E43) -> 5648.6122 | F44: =MAX(0,F38+F43) -> 5648.6122 | G44: =MAX(0,G38+G43) -> 5648.6122 | H44: =MAX(0,H38+H43) -> 5648.6122 | I44: =SUM(C44:H44) -> 22594.449
A45: КПН | C45: =-C44*Допущения!B32*(1-Допущения!B33) -> 0 | D45: =-D44*Допущения!B32*(1-Допущения!B33) -> 0 | E45: =-E44*Допущения!B32*(1-Допущения!B33) -> -1129.7224 | F45: =-F44*Допущения!B32*(1-Допущения!B33) -> -1129.7224 | G45: =-G44*Допущения!B32*(1-Допущения!B33) -> -1129.7224 | H45: =-H44*Допущения!B32*(1-Допущения!B33) -> -1129.7224 | I45: =SUM(C45:H45) -> -4518.8898
A47: СВОБОДНЫЙ ДЕНЕЖНЫЙ ПОТОК
A48: Денежный поток до налога | C48: =C38+C41+C42 -> -8150 | D48: =D38+D41+D42 -> -18000 | E48: =E38+E41+E42 -> 10148.612 | F48: =F38+F41+F42 -> 10148.612 | G48: =G38+G41+G42 -> 10148.612 | H48: =H38+H41+H42 -> 10148.612 | I48: =SUM(C48:H48) -> 14444.449
...

Sheet Сценарии
A1: СЦЕНАРИИ И ЧУВСТВИТЕЛЬНОСТЬ
A3: ТРИ ЦЕНОВЫХ СЦЕНАРИЯ (все прочие параметры одинаковы)
A4: Показатель | B4: Пессимистичный | C4: Базовый | D4: Спот 10.08.2026
A5: Цена золота, $/унц. | B5: =Допущения!B8 -> 2600 | C5: =Допущения!B6 -> 3200 | D5: =Допущения!B7 -> 4376
A6: Цена серебра, $/унц. | B6: =Допущения!B11 -> 35 | C6: =Допущения!B9 -> 45 | D6: =Допущения!B10 -> 65.86
A7: Выручка — золото, $ тыс. | B7: =Проект!$B$15*B5/1000 -> 68963.251 | C7: =Проект!$B$15*C5/1000 -> 84877.848 | D7: =Проект!$B$15*D5/1000 -> 116070.46
A8: Выручка — серебро, $ тыс. | B8: =Проект!$B$16*B6/1000 -> 3516.4828 | C8: =Проект!$B$16*C6/1000 -> 4521.1922 | D8: =Проект!$B$16*D6/1000 -> 6617.0159
A9: Выручка итого, $ тыс. | B9: =B7+B8 -> 72479.734 | C9: =C7+C8 -> 89399.04 | D9: =D7+D8 -> 122687.47
A10: OPEX, $ тыс. | B10: =-Допущения!B17*Допущения!B24 -> -40000 | C10: =-Допущения!B17*Допущения!B24 -> -40000 | D10: =-Допущения!B17*Допущения!B24 -> -40000
A11: НДПИ (коэф. 0,1), $ тыс. | B11: =-B9*Допущения!B30*Допущения!B31 -> -652.31761 | C11: =-C9*Допущения!B30*Допущения!B31 -> -804.59136 | D11: =-D9*Допущения!B30*Допущения!B31 -> -1104.1873
A12: G&A и рекультивация, $ тыс. | B12: =-Допущения!B27 -> -8000 | C12: =-Допущения!B27 -> -8000 | D12: =-Допущения!B27 -> -8000
A13: CAPEX, $ тыс. | B13: =-Допущения!B23 -> -18000 | C13: =-Допущения!B23 -> -18000 | D13: =-Допущения!B23 -> -18000
A14: Покупка актива и DD, $ тыс. | B14: =-(Допущения!B25+Допущения!B26) -> -8150 | C14: =-(Допущения!B25+Допущения!B26) -> -8150 | D14: =-(Допущения!B25+Допущения!B26) -> -8150
A15: Поток до налога на прибыль, $ тыс. | B15: =SUM(B9:B14) -> -2322.5833 | C15: =SUM(C9:C14) -> 14444.449 | D15: =SUM(D9:D14) -> 47433.286
A16: КПН, $ тыс. | B16: =-MAX(0,B9+B10+B11+B12-Допущения!B23)*Допущения!B32*(1-Допущения!B33) -> -1165.4833 | C16: =-MAX(0,C9+C10+C11+C12-Допущения!B23)*Допущения!B32*(1-Допущения!B33) -> -4518.8898 | D16: =-MAX(0,D9+D10+D11+D12-Допущения!B23)*Допущения!B32*(1-Допущения!B33) -> -11116.657
A17: Чистый поток за проект, $ тыс. | B17: =B15+B16 -> -3488.0666 | C17: =C15+C16 -> 9925.5591 | D17: =D15+D16 -> 36316.629
A18: Мультипликатор на вложенное | B18: =IFERROR((B17-B13-B14)/(-B13-B14),0) -> 0.86661313 | C18: =IFERROR((C17-C13-C14)/(-C13-C14),0) -> 1.3795625 | D18: =IFERROR((D17-D13-D14)/(-D13-D14),0) -> 2.3887812
A20: Мультипликатор = (все поступления за проект) / (покупка + CAPEX). Недисконтированный, за весь срок.
A22: ЧУВСТВИТЕЛЬНОСТЬ: чистый поток проекта ($ тыс.) — цена золота × извлечение золота
A23: Цена Au ↓ / Извлечение → | B23: 0.45 | C23: 0.55 | D23: 0.65 | E23: 0.75 | F23: 0.85
A24: 2600 | B24: =(Допущения!$B$17*Допущения!$B$18*B$23*Допущения!$B$14*$A24/1000)+(Допущения!$B$17*Допущения!$B$19*Допущения!$B$21*Допущения!$B$14*Допущения!$B$9/1000)-Допущения!$B$17*Допущения!$B$24-((Допущения!$B$17*Допущения!$B$18*B$23*Допущения!$B$14*$A24/1000)+(Допущения!$B$17*Допущения!$B$19*Допущения!$B$21*Допущения!$B$14*Допущения!$B$9/1000))*Допущения!$B$30*Допущения!$B$31-Допущения!$B$27-Допущения!$B$23-Допущения!$B$25-Допущения!$B$26 -> -13752.84 | C24: =(Допущения!$B$17*Допущения!$B$18*C$23*Допущения!$B$14*$A24/1000)+(Допущения!$B$17*Допущения!$B$19*Допущения!$B$21*Допущения!$B$14*Допущения!$B$9/1000)-Допущения!$B$17*Допущения!$B$24-((Допущения!$B$17*Допущения!$B$18*C$23*Допущения!$B$14*$A24/1000)+(Допущения!$B$17*Допущения!$B$19*Допущения!$B$21*Допущения!$B$14*Допущения!$B$9/1000))*Допущения!$B$30*Допущения!$B$31-Допущения!$B$27-Допущения!$B$23-Допущения!$B$25-Допущения!$B$26 -> -1326.9163 | D24: =(Допущения!$B$17*Допущения!$B$18*D$23*Допущения!$B$14*$A24/1000)+(Допущения!$B$17*Допущения!$B$19*Допущения!$B$21*Допущения!$B$14*Допущения!$B$9/1000)-Допущения!$B$17*Допущения!$B$24-((Допущения!$B$17*Допущения!$B$18*D$23*Допущения!$B$14*$A24/1000)+(Допущения!$B$17*Допущения!$B$19*Допущения!$B$21*Допущения!$B$14*Допущения!$B$9/1000))*Допущения!$B$30*Допущения!$B$31-Допущения!$B$27-Допущения!$B$23-Допущения!$B$25-Допущения!$B$26 -> 11099.008 | E24: =(Допущения!$B$17*Допущения!$B$18*E$23*Допущения!$B$14*$A24/1000)+(Допущения!$B$17*Допущения!$B$19*Допущения!$B$21*Допущения!$B$14*Допущения!$B$9/1000)-Допущения!$B$17*Допущения!$B$24-((Допущения!$B$17*Допущения!$B$18*E$23*Допущения!$B$14*$A24/1000)+(Допущения!$B$17*Допущения!$B$19*Допущения!$B$21*Допущения!$B$14*Допущения!$B$9/1000))*Допущения!$B$30*Допущения!$B$31-Допущения!$B$27-Допущения!$B$23-Допущения!$B$25-Допущения!$B$26 -> 23524.932 | F24: =(Допущения!$B$17*Допущения!$B$18*F$23*Допущения!$B$14*$A24/1000)+(Допущения!$B$17*Допущения!$B$19*Допущения!$B$21*Допущения!$B$14*Допущения!$B$9/1000)-Допущения!$B$17*Допущения!$B$24-((Допущения!$B$17*Допущения!$B$18*F$23*Допущения!$B$14*$A24/1000)+(Допущения!$B$17*Допущения!$B$19*Допущения!$B$21*Допущения!$B$14*Допущения!$B$9/1000))*Допущения!$B$30*Допущения!$B$31-Допущения!$B$27-Допущения!$B$23-Допущения!$B$25-Допущения!$B$26 -> 35950.856
A25: 3000 | B25: =(Допущения!$B$17*Допущения!$B$18*B$23*Допущения!$B$14*$A25/1000)+(Допущения!$B$17*Допущения!$B$19*Допущения!$B$21*Допущения!$B$14*Допущения!$B$9/1000)-Допущения!$B$17*Допущения!$B$24-((Допущения!$B$17*Допущения!$B$18*B$23*Допущения!$B$14*$A25/1000)+(Допущения!$B$17*Допущения!$B$19*Допущения!$B$21*Допущения!$B$14*Допущения!$B$9/1000))*Допущения!$B$30*Допущения!$B$31-Допущения!$B$27-Допущения!$B$23-Допущения!$B$25-Допущения!$B$26 -> -5150.2775 | C25: =(Допущения!$B$17*Допущения!$B$18*C$23*Допущения!$B$14*$A25/1000)+(Допущения!$B$17*Допущения!$B$19*Допущения!$B$21*Допущения!$B$14*Допущения!$B$9/1000)-Допущения!$B$17*Допущения!$B$24-((Допущения!$B$17*Допущения!$B$18*C$23*Допущения!$B$14*$A25/1000)+(Допущения!$B$17*Допущения!$B$19*Допущения!$B$21*Допущения!$B$14*Допущения!$B$9/1000))*Допущения!$B$30*Допущения!$B$31-Допущения!$B$27-Допущения!$B$23-Допущения!$B$25-Допущения!$B$26 -> 9187.3271 | D25: =(Допущения!$B$17*Допущения!$B$18*D$23*Допущения!$B$14*$A25/1000)+(Допущения!$B$17*Допущения!$B$19*Допущения!$B$21*Допущения!$B$14*Допущения!$B$9/1000)-Допущения!$B$17*Допущения!$B$24-((Допущения!$B$17*Допущения!$B$18*D$23*Допущения!$B$14*$A25/1000)+(Допущения!$B$17*Допущения!$B$19*Допущения!$B$21*Допущения!$B$14*Допущения!$B$9/1000))*Допущения!$B$30*Допущения!$B$31-Допущения!$B$27-Допущения!$B$23-Допущения!$B$25-Допущения!$B$26 -> 23524.932 | E25: =(Допущения!$B$17*Допущения!$B$18*E$23*Допущения!$B$14*$A25/1000)+(Допущения!$B$17*Допущения!$B$19*Допущения!$B$21*Допущения!$B$14*Допущения!$B$9/1000)-Допущения!$B$17*Допущения!$B$24-((Допущения!$B$17*Допущения!$B$18*E$23*Допущения!$B$14*$A25/1000)+(Допущения!$B$17*Допущения!$B$19*Допущения!$B$21*Допущения!$B$14*Допущения!$B$9/1000))*Допущения!$B$30*Допущения!$B$31-Допущения!$B$27-Допущения!$B$23-Допущения!$B$25-Допущения!$B$26 -> 37862.536 | F25: =(Допущения!$B$17*Допущения!$B$18*F$23*Допущения!$B$14*$A25/1000)+(Допущения!$B$17*Допущения!$B$19*Допущения!$B$21*Допущения!$B$14*Допущения!$B$9/1000)-Допущения!$B$17*Допущения!$B$24-((Допущения!$B$17*Допущения!$B$18*F$23*Допущения!$B$14*$A25/1000)+(Допущения!$B$17*Допущения!$B$19*Допущения!$B$21*Допущения!$B$14*Допущения!$B$9/1000))*Допущения!$B$30*Допущения!$B$31-Допущения!$B$27-Допущения!$B$23-Допущения!$B$25-Допущения!$B$26 -> 52200.141
A26: 3400 | B26: =(Допущения!$B$17*Допущения!$B$18*B$23*Допущения!$B$14*$A26/1000)+(Допущения!$B$17*Допущения!$B$19*Допущения!$B$21*Допущения!$B$14*Допущения!$B$9/1000)-Допущения!$B$17*Допущения!$B$24-((Допущения!$B$17*Допущения!$B$18*B$23*Допущения!$B$14*$A26/1000)+(Допущения!$B$17*Допущения!$B$19*Допущения!$B$21*Допущения!$B$14*Допущения!$B$9/1000))*Допущения!$B$30*Допущения!$B$31-Допущения!$B$27-Допущения!$B$23-Допущения!$B$25-Допущения!$B$26 -> 3452.2852 | C26: =(Допущения!$B$17*Допущения!$B$18*C$23*Допущения!$B$14*$A26/1000)+(Допущения!$B$17*Допущения!$B$19*Допущения!$B$21*Допущения!$B$14*Допущения!$B$9/1000)-Допущения!$B$17*Допущения!$B$24-((Допущения!$B$17*Допущения!$B$18*C$23*Допущения!$B$14*$A26/1000)+(Допущения!$B$17*Допущения!$B$19*Допущения!$B$21*Допущения!$B$14*Допущения!$B$9/1000))*Допущения!$B$30*Допущения!$B$31-Допущения!$B$27-Допущения!$B$23-Допущения!$B$25-Допущения!$B$26 -> 19701.571 | D26: =(Допущения!$B$17*Допущения!$B$18*D$23*Допущения!$B$14*$A26/1000)+(Допущения!$B$17*Допущения!$B$19*Допущения!$B$21*Допущения!$B$14*Допущения!$B$9/1000)-Допущения!$B$17*Допущения!$B$24-((Допущения!$B$17*Допущения!$B$18*D$23*Допущения!$B$14*$A26/1000)+(Допущения!$B$17*Допущения!$B$19*Допущения!$B$21*Допущения!$B$14*Допущения!$B$9/1000))*Допущения!$B$30*Допущения!$B$31-Допущения!$B$27-Допущения!$B$23-Допущения!$B$25-Допущения!$B$26 -> 35950.856 | E26: =(Допущения!$B$17*Допущения!$B$18*E$23*Допущения!$B$14*$A26/1000)+(Допущения!$B$17*Допущения!$B$19*Допущения!$B$21*Допущения!$B$14*Допущения!$B$9/1000)-Допущения!$B$17*Допущения!$B$24-((Допущения!$B$17*Допущения!$B$18*E$23*Допущения!$B$14*$A26/1000)+(Допущения!$B$17*Допущения!$B$19*Допущения!$B$21*Допущения!$B$14*Допущения!$B$9/1000))*Допущения!$B$30*Допущения!$B$31-Допущения!$B$27-Допущения!$B$23-Допущения!$B$25-Допущения!$B$26 -> 52200.141 | F26: =(Допущения!$B$17*Допущения!$B$18*F$23*Допущения!$B$14*$A26/1000)+(Допущения!$B$17*Допущения!$B$19*Допущения!$B$21*Допущения!$B$14*Допущения!$B$9/1000)-Допущения!$B$17*Допущения!$B$24-((Допущения!$B$17*Допущения!$B$18*F$23*Допущения!$B$14*$A26/1000)+(Допущения!$B$17*Допущения!$B$19*Допущения!$B$21*Допущения!$B$14*Допущения!$B$9/1000))*Допущения!$B$30*Допущения!$B$31-Допущения!$B$27-Допущения!$B$23-Допущения!$B$25-Допущения!$B$26 -> 68449.426
A27: 3800 | B27: =(Допущения!$B$17*Допущения!$B$18*B$23*Допущения!$B$14*$A27/1000)+(Допущения!$B$17*Допущения!$B$19*Допущения!$B$21*Допущения!$B$14*Допущения!$B$9/1000)-Допущения!$B$17*Допущения!$B$24-((Допущения!$B$17*Допущения!$B$18*B$23*Допущения!$B$14*$A27/1000)+(Допущения!$B$17*Допущения!$B$19*Допущения!$B$21*Допущения!$B$14*Допущения!$B$9/1000))*Допущения!$B$30*Допущения!$B$31-Допущения!$B$27-Допущения!$B$23-Допущения!$B$25-Допущения!$B$26 -> 12054.848 | C27: =(Допущения!$B$17*Допущения!$B$18*C$23*Допущения!$B$14*$A27/1000)+(Допущения!$B$17*Допущения!$B$19*Допущения!$B$21*Допущения!$B$14*Допущения!$B$9/1000)-Допущения!$B$17*Допущения!$B$24-((Допущения!$B$17*Допущения!$B$18*C$23*Допущения!$B$14*$A27/1000)+(Допущения!$B$17*Допущения!$B$19*Допущения!$B$21*Допущения!$B$14*Допущения!$B$9/1000))*Допущения!$B$30*Допущения!$B$31-Допущения!$B$27-Допущения!$B$23-Допущения!$B$25-Допущения!$B$26 -> 30215.814 | D27: =(Допущения!$B$17*Допущения!$B$18*D$23*Допущения!$B$14*$A27/1000)+(Допущения!$B$17*Допущения!$B$19*Допущения!$B$21*Допущения!$B$14*Допущения!$B$9/1000)-Допущения!$B$17*Допущения!$B$24-((Допущения!$B$17*Допущения!$B$18*D$23*Допущения!$B$14*$A27/1000)+(Допущения!$B$17*Допущения!$B$19*Допущения!$B$21*Допущения!$B$14*Допущения!$B$9/1000))*Допущения!$B$30*Допущения!$B$31-Допущения!$B$27-Допущения!$B$23-Допущения!$B$25-Допущения!$B$26 -> 48376.78 | E27: =(Допущения!$B$17*Допущения!$B$18*E$23*Допущения!$B$14*$A27/1000)+(Допущения!$B$17*Допущения!$B$19*Допущения!$B$21*Допущения!$B$14*Допущения!$B$9/1000)-Допущения!$B$17*Допущения!$B$24-((Допущения!$B$17*Допущения!$B$18*E$23*Допущения!$B$14*$A27/1000)+(Допущения!$B$17*Допущения!$B$19*Допущения!$B$21*Допущения!$B$14*Допущения!$B$9/1000))*Допущения!$B$30*Допущения!$B$31-Допущения!$B$27-Допущения!$B$23-Допущения!$B$25-Допущения!$B$26 -> 66537.746 | F27: =(Допущения!$B$17*Допущения!$B$18*F$23*Допущения!$B$14*$A27/1000)+(Допущения!$B$17*Допущения!$B$19*Допущения!$B$21*Допущения!$B$14*Допущения!$B$9/1000)-Допущения!$B$17*Допущения!$B$24-((Допущения!$B$17*Допущения!$B$18*F$23*Допущения!$B$14*$A27/1000)+(Допущения!$B$17*Допущения!$B$19*Допущения!$B$21*Допущения!$B$14*Допущения!$B$9/1000))*Допущения!$B$30*Допущения!$B$31-Допущения!$B$27-Допущения!$B$23-Допущения!$B$25-Допущения!$B$26 -> 84698.712
A28: 4376 | B28: =(Допущения!$B$17*Допущения!$B$18*B$23*Допущения!$B$14*$A28/1000)+(Допущения!$B$17*Допущения!$B$19*Допущения!$B$21*Допущения!$B$14*Допущения!$B$9/1000)-Допущения!$B$17*Допущения!$B$24-((Допущения!$B$17*Допущения!$B$18*B$23*Допущения!$B$14*$A28/1000)+(Допущения!$B$17*Допущения!$B$19*Допущения!$B$21*Допущения!$B$14*Допущения!$B$9/1000))*Допущения!$B$30*Допущения!$B$31-Допущения!$B$27-Допущения!$B$23-Допущения!$B$25-Допущения!$B$26 -> 24442.538 | C28: =(Допущения!$B$17*Допущения!$B$18*C$23*Допущения!$B$14*$A28/1000)+(Допущения!$B$17*Допущения!$B$19*Допущения!$B$21*Допущения!$B$14*Допущения!$B$9/1000)-Допущения!$B$17*Допущения!$B$24-((Допущения!$B$17*Допущения!$B$18*C$23*Допущения!$B$14*$A28/1000)+(Допущения!$B$17*Допущения!$B$19*Допущения!$B$21*Допущения!$B$14*Допущения!$B$9/1000))*Допущения!$B$30*Допущения!$B$31-Допущения!$B$27-Допущения!$B$23-Допущения!$B$25-Допущения!$B$26 -> 45356.324 | D28: =(Допущения!$B$17*Допущения!$B$18*D$23*Допущения!$B$14*$A28/1000)+(Допущения!$B$17*Допущения!$B$19*Допущения!$B$21*Допущения!$B$14*Допущения!$B$9/1000)-Допущения!$B$17*Допущения!$B$24-((Допущения!$B$17*Допущения!$B$18*D$23*Допущения!$B$14*$A28/1000)+(Допущения!$B$17*Допущения!$B$19*Допущения!$B$21*Допущения!$B$14*Допущения!$B$9/1000))*Допущения!$B$30*Допущения!$B$31-Допущения!$B$27-Допущения!$B$23-Допущения!$B$25-Допущения!$B$26 -> 66270.11 | E28: =(Допущения!$B$17*Допущения!$B$18*E$23*Допущения!$B$14*$A28/1000)+(Допущения!$B$17*Допущения!$B$19*Допущения!$B$21*Допущения!$B$14*Допущения!$B$9/1000)-Допущения!$B$17*Допущения!$B$24-((Допущения!$B$17*Допущения!$B$18*E$23*Допущения!$B$14*$A28/1000)+(Допущения!$B$17*Допущения!$B$19*Допущения!$B$21*Допущения!$B$14*Допущения!$B$9/1000))*Допущения!$B$30*Допущения!$B$31-Допущения!$B$27-Допущения!$B$23-Допущения!$B$25-Допущения!$B$26 -> 87183.896 | F28: =(Допущения!$B$17*Допущения!$B$18*F$23*Допущения!$B$14*$A28/1000)+(Допущения!$B$17*Допущения!$B$19*Допущения!$B$21*Допущения!$B$14*Допущения!$B$9/1000)-Допущения!$B$17*Допущения!$B$24-((Допущения!$B$17*Допущения!$B$18*F$23*Допущения!$B$14*$A28/1000)+(Допущения!$B$17*Допущения!$B$19*Допущения!$B$21*Допущения!$B$14*Допущения!$B$9/1000))*Допущения!$B$30*Допущения!$B$31-Допущения!$B$27-Допущения!$B$23-Допущения!$B$25-Допущения!$B$26 -> 108097.68
A30: Сетка считает недисконтированный поток до КПН при базовой цене серебра. Видно, что рост извлечения на 10 п.п. добавляет больше, чем весь CAPEX фабрики: металлургические тесты — самая доходная строка бюджета due diligence.

Sheet Фонд
A1: ЭКОНОМИКА ФОНДА I — $30M, 2/20, hurdle 8%, срок 10 лет
A3: ПАРАМЕТРЫ
A4: Обязательства (commitments), $ тыс. | B4: =Допущения!B37 -> 30000
A5: GP commit, $ тыс. | B5: =Допущения!B37*Допущения!B38 -> 450
A6: Management fee | B6: =Допущения!B39 -> 0.02
A7: Carried interest | B7: =Допущения!B40 -> 0.2
A8: Hurdle | B8: =Допущения!B41 -> 0.08
A9: Валовой мультипликатор (сценарий) | B9: =Допущения!B45 -> 2.6
A11: ДВИЖЕНИЕ ДЕНЕГ ПО ГОДАМ, $ тыс.
A12: Показатель | B12: Год 1 | C12: Год 2 | D12: Год 3 | E12: Год 4 | F12: Год 5 | G12: Год 6 | H12: Год 7 | I12: Год 8 | J12: Год 9 | K12: Год 10 | L12: ИТОГО
A13: Профиль вызовов капитала, % | B13: 0.2 | C13: 0.25 | D13: 0.25 | E13: 0.2 | F13: 0.1 | G13: 0 | H13: 0 | I13: 0 | J13: 0 | K13: 0 | L13: =SUM(B13:K13) -> 1
A14: Профиль распределений, % | B14: 0 | C14: 0 | D14: 0 | E14: 0.044 | F14: 0.087 | G14: 0.145 | H14: 0.203 | I14: 0.232 | J14: 0.174 | K14: 0.115 | L14: =SUM(B14:K14) -> 1
A16: Вызовы капитала | B16: =B13*$B$4 -> 6000 | C16: =C13*$B$4 -> 7500 | D16: =D13*$B$4 -> 7500 | E16: =E13*$B$4 -> 6000 | F16: =F13*$B$4 -> 3000 | G16: =G13*$B$4 -> 0 | H16: =H13*$B$4 -> 0 | I16: =I13*$B$4 -> 0 | ... K16: =K13*$B$4 -> 0 | L16: =SUM(B16:K16) -> 30000
A17: Management fee | B17: =$B$6*$B$4 -> 600 | C17: =$B$6*$B$4 -> 600 | D17: =$B$6*$B$4 -> 600 | E17: =$B$6*$B$4 -> 600 | F17: =$B$6*$B$4 -> 600 | G17: =$B$6*$B$21*(1-SUM($B$14:F$14)) -> 464.046 | H17: =$B$6*$B$21*(1-SUM($B$14:G$14)) -> 386.616 | I17: =$B$6*$B$21*(1-SUM($B$14:H$14)) -> 278.214 | J17: =$B$6*$B$21*(1-SUM($B$14:I$14)) -> 154.326 | K17: =$B$6*$B$21*(1-SUM($B$14:J$14)) -> 61.41 | L17: =SUM(B17:K17) -> 4344.612
A18: Распределения (валовые) | B18: =B14*$B$22 -> 0 | C18: =C14*$B$22 -> 0 | D18: =D14*$B$22 -> 0 | E18: =E14*$B$22 -> 3054.48 | F18: =F14*$B$22 -> 6039.54 | G18: =G14*$B$22 -> 10065.9 | H18: =H14*$B$22 -> 14092.26 | I18: =I14*$B$22 -> 16105.44 | ... K18: =K14*$B$22 -> 7983.3 | L18: =SUM(B18:K18) -> 69420
A20: СВОДКА
A21: Инвестировано в активы, $ тыс. | B21: =$B$4-SUM(B17:F17)-Допущения!B44 -> 26700 | D21: Обязательства минус fee инвестиционного периода минус организационные расходы
A22: Валовые распределения, $ тыс. | B22: =$B$21*$B$9 -> 69420 | D22: Инвестировано × валовой мультипликатор
A23: Management fee за весь срок, $ тыс. | B23: =L17 -> 4344.612 | D23: Основной предсказуемый доход управляющего
A24: Прибыль фонда, $ тыс. | B24: =$B$22-$B$4 -> 39420 | D24: Распределения минус возврат капитала
A25: Накопленный preferred return, $ тыс. | B25: =$B$4*((1+$B$8)^Допущения!B42-1) -> 14079.842 | D25: Порог, выше которого возникает carry
A26: Hurdle пройден? | B26: =IF($B$24>$B$25,"ДА","НЕТ") -> ДА | D26: Если НЕТ — carry равен нулю
A27: Carried interest GP, $ тыс. | B27: =IF($B$24>$B$25,$B$24*$B$7,0) -> 7884 | D27: Упрощение: при прохождении hurdle применяется полный catch-up
A28: Получают LP, $ тыс. | B28: =$B$22-$B$27 -> 61536
A29: Чистый мультипликатор LP | B29: =IFERROR($B$28/$B$4,0) -> 2.0512
A30: Чистый IRR LP | B30: =IFERROR(IRR(B32:K32),0) -> 0.16754597 | D30: По чистому потоку LP ниже
A31: Доход GP за 10 лет (fee + carry), $ тыс. | B31: =$B$23+$B$27 -> 12228.612 | D31: Из fee финансируется офис — это не прибыль
A32: Чистый денежный поток LP по годам, $ тыс. | B32: =-B16+B18*(1-IFERROR($B$27/$B$22,0)) -> -6000 | C32: =-C16+C18*(1-IFERROR($B$27/$B$22,0)) -> -7500 | D32: =-D16+D18*(1-IFERROR($B$27/$B$22,0)) -> -7500 | E32: =-E16+E18*(1-IFERROR($B$27/$B$22,0)) -> -3292.416 | F32: =-F16+F18*(1-IFERROR($B$27/$B$22,0)) -> 2353.632 | G32: =-G16+G18*(1-IFERROR($B$27/$B$22,0)) -> 8922.72 | H32: =-H16+H18*(1-IFERROR($B$27/$B$22,0)) -> 12491.808 | I32: =-I16+I18*(1-IFERROR($B$27/$B$22,0)) -> 14276.352 | ... K32: =-K16+K18*(1-IFERROR($B$27/$B$22,0)) -> 7076.64 | L32: =SUM(B32:K32) -> 31536
A34: Упрощение waterfall: carry распределён пропорционально по всем распределениям, чтобы получить корректный IRR. В реальном LPA (европейский waterfall) carry начинает выплачиваться только после полного возврата капитала LP и preferred return — итоговые суммы те же, распределение во времени иное.
A37: СЦЕНАРИИ ФОНДА
A38: Показатель | B38: Слабый | C38: Базовый | D38: Отличный
A39: Валовой мультипликатор | B39: =Допущения!B47 -> 1.6 | C39: =Допущения!B45 -> 2.6 | D39: =Допущения!B46 -> 3.5
A40: Валовые распределения, $ тыс. | B40: =$B$21*B39 -> 42720 | C40: =$B$21*C39 -> 69420 | D40: =$B$21*D39 -> 93450
A41: Прибыль фонда, $ тыс. | B41: =B40-$B$4 -> 12720 | C41: =C40-$B$4 -> 39420 | D41: =D40-$B$4 -> 63450
A42: Hurdle пройден? | B42: =IF(B41>$B$25,"ДА","НЕТ") -> НЕТ | C42: =IF(C41>$B$25,"ДА","НЕТ") -> ДА | D42: =IF(D41>$B$25,"ДА","НЕТ") -> ДА
A43: Carry GP, $ тыс. | B43: =IF(B41>$B$25,B41*$B$7,0) -> 0 | C43: =IF(C41>$B$25,C41*$B$7,0) -> 7884 | D43: =IF(D41>$B$25,D41*$B$7,0) -> 12690
A44: Чистый мультипликатор LP | B44: =IFERROR((B40-B43)/$B$4,0) -> 1.424 | C44: =IFERROR((C40-C43)/$B$4,0) -> 2.0512 | D44: =IFERROR((D40-D43)/$B$4,0) -> 2.692
A45: Доход GP всего (fee+carry), $ тыс. | B45: =$B$23+B43 -> 4344.612 | C45: =$B$23+C43 -> 12228.612 | D45: =$B$23+D43 -> 17034.612
A47: Ключевой вывод: в слабом сценарии carry равен нулю, и управляющий за 10 лет получает только management fee, из которого содержится офис. Carry — это опцион, а не зарплата. Поэтому доход от сделок (fee за организацию, плата за управление проектом, промоут, роялти) критичен: он не зависит от того, сработает ли фонд.

Sheet Бюджет
A1: БЮДЖЕТ ОФИСА
A3: Доля от максимума для колонки «План» (0 = минимум, 1 = максимум) | B3: 0.4
A5: РАЗОВЫЕ РАСХОДЫ НА ЗАПУСК (месяцы 0–3), $
A6: Статья | B6: Минимум | C6: Максимум | D6: План | E6: Комментарий
A7: Регистрация AIFC Private Company (управляющая) | B7: 300 | C7: 500 | D7: =B7+(C7-B7)*$B$3 -> 380 | E7: Онлайн-подача, Schedule 5 AIFC Fees Rules
A8: Регистрация AIFC Private Company (проектный холдинг) | B8: 300 | C8: 500 | D8: =B8+(C8-B8)*$B$3 -> 380 | E8: Одна компания на сделку
A9: Регистрация ТОО в Алматы | B9: 500 | C9: 1500 | D9: =B9+(C9-B9)*$B$3 -> 900 | E9: Операционная компания: офис, зарплаты
A10: Юридическое структурирование | B10: 5000 | C10: 12000 | D10: =B10+(C10-B10)*$B$3 -> 7800 | E10: Схема владения, налоговая проработка
A11: Зарегистрированный офис в МФЦА, год 1 | B11: 1200 | C11: 2400 | D11: =B11+(C11-B11)*$B$3 -> 1680 | E11: Обязателен адрес в границах МФЦА (Астана)
A12: Открытие банковских счетов | B12: 1000 | C12: 3000 | D12: =B12+(C12-B12)*$B$3 -> 1800 | E12: Проверить проходимость комплаенса ДО сделки
A13: Технический DD (бурение, пробы, металлургия, CPR) | B13: 80000 | C13: 160000 | D13: =B13+(C13-B13)*$B$3 -> 112000 | E13: 1–2% от суммы сделки. Единственная статья, на которой нельзя экономить
A14: Юридический DD по сделке | B14: 15000 | C14: 30000 | D14: =B14+(C14-B14)*$B$3 -> 21000 | E14: Включая проверку статуса ТМО по ст. 13 Кодекса о недрах
A15: Финансовый и налоговый DD | B15: 8000 | C15: 18000 | D15: =B15+(C15-B15)*$B$3 -> 12000 | E15: Плюс заключение по применимости коэффициента 0,1 к НДПИ
A16: Экологический аудит | B16: 8000 | C16: 20000 | D16: =B16+(C16-B16)*$B$3 -> 12800 | E16: Обязательства по рекультивации переходят к покупателю
A17: Документация сделки (SPA, SHA, escrow) | B17: 15000 | C17: 35000 | D17: =B17+(C17-B17)*$B$3 -> 23000 | E17: Отлагательные условия и защита инвесторов
A18: Материалы для инвесторов (тизер, IM, модель, бренд) | B18: 8000 | C18: 20000 | D18: =B18+(C18-B18)*$B$3 -> 12800 | E18: Формат сразу под требования KAZRC/JORC
A19: ИТОГО | B19: =SUM(B7:B18) -> 142300 | C19: =SUM(C7:C18) -> 302900 | D19: =SUM(D7:D18) -> 206540
A21: ОПЕРАЦИОННЫЕ РАСХОДЫ, ГОД 1, $
A22: Статья | B22: Минимум | C22: Максимум | D22: План | E22: Комментарий
A23: Зарплаты (3 человека, с налогами работодателя) | B23: 106000 | C23: 165000 | D23: =B23+(C23-B23)*$B$3 -> 129600 | E23: Детализация ниже
A24: Офис в Алматы (аренда, связь, оборудование) | B24: 12000 | C24: 30000 | D24: =B24+(C24-B24)*$B$3 -> 19200 | E24: 3–5 рабочих мест
A25: AI, данные, софт | B25: 12000 | C25: 36000 | D25: =B25+(C25-B25)*$B$3 -> 21600 | E25: Детализация ниже
A26: Поддержание структуры МФЦА | B26: 6000 | C26: 18000 | D26: =B26+(C26-B26)*$B$3 -> 10800 | E26: Продление, корпоративный секретарь, комплаенс
A27: Юридический и налоговый ретейнер | B27: 12000 | C27: 30000 | D27: =B27+(C27-B27)*$B$3 -> 19200 | E27: Недропользование + корпоративное право
A28: Аудит | B28: 5000 | C28: 12000 | D28: =B28+(C28-B28)*$B$3 -> 7800 | E28: С первого года — это требование инвесторов, а не регулятора
A29: Поездки к инвесторам (ОАЭ, Израиль, Китай, Индия, СНГ) | B29: 30000 | C29: 60000 | D29: =B29+(C29-B29)*$B$3 -> 42000 | E29: Деньги привлекаются лично
A30: Прочее и резерв | B30: 18000 | C30: 35000 | D30: =B30+(C30-B30)*$B$3 -> 24800 | E30: 10% на непредвиденное
A31: ИТОГО | B31: =SUM(B23:B30) -> 201000 | C31: =SUM(C23:C30) -> 386000 | D31: =SUM(D23:D30) -> 275000
A33: ДОПОЛНИТЕЛЬНО ПРИ ЗАПУСКЕ ФОНДА (месяцы 6–18), $
A34: Статья | B34: Минимум | C34: Максимум | D34: План | E34: Комментарий
A35: Сбор AFSA за заявку на лицензию Fund Manager | B35: 5000 | C35: 5000 | D35: =B35+(C35-B35)*$B$3 -> 5000 | E35: AIFC Fees Rules
A36: Ежегодный надзорный сбор AFSA | B36: 3000 | C36: 3000 | D36: =B36+(C36-B36)*$B$3 -> 3000 | E36: AIFC Fees Rules
A37: Подготовка лицензионного пакета | B37: 25000 | C37: 60000 | D37: =B37+(C37-B37)*$B$3 -> 39000 | E37: Бизнес-план 3 года, AML/CFT, риск-менеджмент, назначенные лица
A38: Уведомление об Exempt Fund | B38: 1000 | C38: 1000 | D38: =B38+(C38-B38)*$B$3 -> 1000 | E38: Не регистрация, а уведомление — минимум за 7 дней до запуска
A39: Документация фонда (LPA, PPM, подписные) | B39: 35000 | C39: 90000 | D39: =B39+(C39-B39)*$B$3 -> 57000 | E39: Главный документ отношений с инвесторами
A40: Администратор фонда (запуск + год) | B40: 25000 | C40: 60000 | D40: =B40+(C40-B40)*$B$3 -> 39000 | E40: Внешний администратор — требование серьёзных LP
A41: Кастодиан (год) | B41: 10000 | C41: 30000 | D41: =B41+(C41-B41)*$B$3 -> 18000 | E41: Снижает требование к капиталу управляющего с $500k до $50k
A42: Аудитор фонда (год) | B42: 10000 | C42: 25000 | D42: =B42+(C42-B42)*$B$3 -> 16000 | E42: Обязателен для регистрации фонда в AFSA
A43: Комплаенс-офицер и MLRO | B43: 6000 | C43: 18000 | D43: =B43+(C43-B43)*$B$3 -> 10800 | E43: Можно на аутсорсе
A44: ИТОГО | B44: =SUM(B35:B43) -> 120000 | C44: =SUM(C35:C43) -> 292000 | D44: =SUM(D35:D43) -> 188800
...
